2020-03-12 15:24:31 ERROR [12412-Thread-1] log.log_response line 222: Internal Server Error: /base_app2/index2
Traceback (most recent call last):
  File "F:\software\Python38\lib\site-packages\django\urls\base.py", line 72, in reverse
    extra, resolver = resolver.namespace_dict[ns]
KeyError: 'djdt'

During handling of the above exception, another exception occurred:

Traceback (most recent call last):
  File "F:\software\Python38\lib\site-packages\django\core\handlers\exception.py", line 34, in inner
    response = get_response(request)
  File "F:\software\Python38\lib\site-packages\debug_toolbar\middleware.py", line 99, in __call__
    bits[-2] += toolbar.render_toolbar()
  File "F:\software\Python38\lib\site-packages\debug_toolbar\toolbar.py", line 69, in render_toolbar
    return render_to_string("debug_toolbar/base.html", context)
  File "F:\software\Python38\lib\site-packages\django\template\loader.py", line 62, in render_to_string
    return template.render(context, request)
  File "F:\software\Python38\lib\site-packages\django\template\backends\django.py", line 61, in render
    return self.template.render(context)
  File "F:\software\Python38\lib\site-packages\django\template\base.py", line 171, in render
    return self._render(context)
  File "F:\software\Python38\lib\site-packages\django\test\utils.py", line 95, in instrumented_test_render
    return self.nodelist.render(context)
  File "F:\software\Python38\lib\site-packages\django\template\base.py", line 936, in render
    bit = node.render_annotated(context)
  File "F:\software\Python38\lib\site-packages\django\template\base.py", line 903, in render_annotated
    return self.render(context)
  File "F:\software\Python38\lib\site-packages\django\template\defaulttags.py", line 309, in render
    return nodelist.render(context)
  File "F:\software\Python38\lib\site-packages\django\template\base.py", line 936, in render
    bit = node.render_annotated(context)
  File "F:\software\Python38\lib\site-packages\django\template\base.py", line 903, in render_annotated
    return self.render(context)
  File "F:\software\Python38\lib\site-packages\django\template\defaulttags.py", line 443, in render
    url = reverse(view_name, args=args, kwargs=kwargs, current_app=current_app)
  File "F:\software\Python38\lib\site-packages\django\urls\base.py", line 83, in reverse
    raise NoReverseMatch("%s is not a registered namespace" % key)
django.urls.exceptions.NoReverseMatch: 'djdt' is not a registered namespace
2020-03-12 15:24:31 ERROR [12412-Thread-1] basehttp.log_message line 157: "GET /base_app2/index2 HTTP/1.1" 500 132885
2020-03-12 15:41:41 WARNING [13392-Thread-1] log.log_response line 222: Not Found: /echarts_teacher
2020-03-12 15:41:41 WARNING [13392-Thread-1] basehttp.log_message line 157: "GET /echarts_teacher HTTP/1.1" 404 11628
2020-03-12 15:42:55 WARNING [13392-Thread-3] log.log_response line 222: Not Found: /export/xls/
2020-03-12 15:42:55 WARNING [13392-Thread-3] basehttp.log_message line 157: "GET /export/xls/ HTTP/1.1" 404 11616
2020-03-12 15:44:08 WARNING [6308-Thread-1] log.log_response line 222: Not Found: /export/xls/
2020-03-12 15:44:08 WARNING [6308-Thread-1] basehttp.log_message line 157: "GET /export/xls/ HTTP/1.1" 404 11616
2020-03-12 15:44:14 WARNING [6308-Thread-2] log.log_response line 222: Not Found: /export/xls/
2020-03-12 15:44:14 WARNING [6308-Thread-2] basehttp.log_message line 157: "GET /export/xls/ HTTP/1.1" 404 11616
